Workbook

Sheet 🏠 Trang Bìa
B2: YUP EDUCATION
B3: BẢN CHỤP X-QUANG 50 TIÊU CHÍ VẬN HÀNH BỀN VỮNG
B4: CÔNG CỤ CHẨN ĐOÁN SỨC KHỎE DOANH NGHIỆP · YUP Giải Mã 2026
B6: Tên doanh nghiệp / cửa hàng: ______________________________ Ngày chẩn đoán: _______________
B8: 📋 HƯỚNG DẪN SỬ DỤNG (20–30 phút)
B9: BƯỚC 1 | C9: Mở sheet '📝 Bảng Chẩn Đoán'.
B10: BƯỚC 2 | C10: Với mỗi tiêu chí, đọc CÂU HỎI rồi chọn một trong 3 đáp án trong cột màu vàng: ✅ Có hệ thống → Đang làm tốt, nhất quán, có thể chứng minh bằng số liệu 🔄 Đang xây dựng → Đã bắt đầu nhưng chưa nhất quán hoặc chưa thành hệ thống ❌ Chưa có → Chưa làm, làm theo cảm tính hoặc chưa bao giờ nghĩ đến
B11: BƯỚC 3 | C11: Đọc mô tả 3 đáp án ở các cột bên cạnh nếu chưa chắc mình đang ở mức nào.
B12: BƯỚC 4 | C12: Mở sheet '📈 Kết Quả & Chẩn Đoán' — điểm số tự động hiện ra.
B13: BƯỚC 5 | C13: Mang kết quả đến Buổi 2 để YUP hỗ trợ lập Lộ trình hành động 90 ngày.
B15: 🎯 THANG ĐIỂM · Tổng tối đa 100 điểm
B16: ✅ Có hệ thống | C16: 2 điểm | D16: Đang làm tốt, nhất quán và có thể chứng minh
B17: 🔄 Đang xây dựng | C17: 1 điểm | D17: Đã bắt đầu nhưng chưa ổn định, còn phụ thuộc vào người
B18: ❌ Chưa có | C18: 0 điểm | D18: Chưa làm, làm theo cảm tính hoặc không biết bắt đầu từ đâu
B20: 🏛️ 5 TRỤ CỘT · 10 tiêu chí mỗi trụ · Tối đa 20 điểm/trụ
B21: I. TÀI CHÍNH & DÒNG TIỀN | C21: Phát hiện lãi ảo, dòng tiền âm, lỗ hổng thuế và rủi ro pháp lý 2026
B22: II. DOANH THU & KHÁCH HÀNG | C22: Đánh giá khả năng giữ chân khách, hiệu quả marketing và đa dạng doanh thu
B23: III. VẬN HÀNH & QUY TRÌNH | C23: Kiểm tra SOP, kiểm soát kho, phát hiện thất thoát và năng suất vận hành
B24: IV. NHÂN SỰ & ĐỘI NGŨ | C24: Chẩn đoán năng lực đội ngũ, khả năng phân quyền và văn hóa nội bộ
B25: V. LÃNH ĐẠO & TĂNG TRƯỞNG | C25: Tư duy chủ, sự sẵn sàng mở rộng và nền tảng pháp lý bền vững
B26: © YUP Education · Tài liệu độc quyền – Lưu hành nội bộ · Giải Mã 2026

Sheet 📝 Bảng Chẩn Đoán
A1: 📝 BẢNG CHẨN ĐOÁN · 50 TIÊU CHÍ · 3 BẬC · YUP Education – Giải Mã 2026
A2: Đọc câu hỏi → Chọn đáp án trong cột vàng → Đọc mô tả 3 cột bên phải nếu chưa chắc
B3: # | C3: Câu hỏi chẩn đoán | D3: Đáp án của bạn (chọn từ dropdown) | E3: ✅ Có hệ thống (2 điểm) | F3: 🔄 Đang xây dựng (1 điểm) | G3: ❌ Chưa có (0 điểm) | H3: Ghi chú / Bằng chứng thực tế
A4: I. TÀI CHÍNH & DÒNG TIỀN (Tiêu chí #1 – #10)
B5: 1 | C5: Tài khoản ngân hàng kinh doanh có được tách biệt hoàn toàn với tài khoản cá nhân? | D5: 🔄 Đang xây dựng | E5: Có tài khoản riêng, KHÔNG có giao dịch cá nhân lẫn vào | F5: Có tài khoản riêng nhưng đôi khi vẫn dùng lẫn với cá nhân | G5: Dùng chung một tài khoản cho cả kinh doanh và cá nhân
B6: 2 | C6: Bạn phân biệt được 'Lãi Thật' (tiền mặt thực có) với 'Lãi Ảo' (lãi trên sổ sách nhưng tiền đang bị chôn ở hàng tồn/công nợ)? | D6: 🔄 Đang xây dựng | E6: Theo dõi cả hai, biết ngay con số mỗi cuối tháng | F6: Hiểu khái niệm nhưng chưa theo dõi thường xuyên | G6: Không phân biệt được, chỉ nhìn vào doanh thu
B7: 3 | C7: Bạn biết điểm hòa vốn (doanh thu tối thiểu để không lỗ) của tháng này là bao nhiêu? | D7: 🔄 Đang xây dựng | E7: Biết con số chính xác và theo dõi hàng tháng | F7: Biết ước chừng nhưng chưa tính chính xác | G7: Không biết, chưa bao giờ tính
B8: 4 | C8: Doanh nghiệp có quỹ dự phòng để vận hành tiếp nếu tháng tới doanh thu giảm mạnh? | D8: ✅ Có hệ thống | E8: Có quỹ dự phòng ≥ 2 tháng chi phí vận hành | F8: Có dự phòng nhưng chỉ đủ dưới 1 tháng | G8: Không có quỹ dự phòng, tháng nào tiêu tháng đó
B9: 5 | C9: Toàn bộ chi phí cố định hàng tháng có được liệt kê đầy đủ và xem xét định kỳ? | D9: ✅ Có hệ thống | E9: Có bảng chi phí đầy đủ, xem lại ít nhất mỗi quý | F9: Có liệt kê nhưng chưa đầy đủ hoặc lâu không cập nhật | G9: Chưa bao giờ liệt kê, không biết tổng chi phí cố định
B10: 6 | C10: Toàn bộ doanh thu (tiền mặt, chuyển khoản, ví điện tử) có được ghi nhận đầy đủ vào một hệ thống theo dõi duy nhất? | D10: ✅ Có hệ thống | E10: 100% doanh thu được ghi nhận, có thể truy xuất bất kỳ lúc nào | F10: Phần lớn được ghi nhận nhưng vẫn có khoản thu ngoài hệ thống | G10: Không ghi nhận đủ, chủ yếu nhớ trong đầu hoặc ghi tay rời rạc
B11: 7 | C11: Dòng tiền thực tế (tiền trong tài khoản) có khớp với doanh thu — tức không xảy ra tình trạng doanh thu cao nhưng hết tiền mặt? | D11: ✅ Có hệ thống | E11: Dòng tiền luôn dương, không bị hụt tiền cuối tháng | F11: Thỉnh thoảng bị căng tiền dù doanh thu ổn | G11: Thường xuyên hết tiền trước cuối tháng dù báo cáo có lãi
B12: 8 | C12: Công nợ khách hàng còn nợ (nếu có) có được theo dõi có hện thanh toán và quy trình đòi nợ rõ ràng? | D12: ✅ Có hệ thống | E12: Có danh sách công nợ chi tiết, có hạn thanh toán và nhắc tự động | F12: Có theo dõi nhưng không nhất quán, hay bị bỏ sót | G12: Không theo dõi, không biết ai đang nợ mình bao nhiêu
B13: 9 | C13: Doanh nghiệp đang kê khai thuế đúng hạn và không có khoản phạt hay vi phạm thuế tồn đọng? | D13: ✅ Có hệ thống | E13: Kê khai đúng hạn, không có phạt, sổ sách minh bạch | F13: Cơ bản đúng hạn nhưng còn một số khoản chưa rõ ràng | G13: Đang có vi phạm hoặc kê khai không đầy đủ
B14: 10 | C14: Bạn có thể trả lời ngay 'Tháng trước lãi (hoặc lỗ) bao nhiêu tiền thực tế?' mà không cần tra sổ? | D14: ✅ Có hệ thống | E14: Biết ngay, có thể trả lời trong vòng 1 phút | F14: Biết gần đúng nhưng phải tra lại để có số chính xác | G14: Không biết, phải mất nhiều thời gian mới tính được
A15: II. DOANH THU & KHÁCH HÀNG (Tiêu chí #11 – #20)
B16: 11 | C16: Tỷ lệ khách hàng cũ quay lại mua tiếp (không cần chạy quảng cáo lại) đang ở mức nào? | D16: ❌ Chưa có | E16: Hơn 40% doanh thu đến từ khách cũ tự quay lại | F16: Có khách quay lại nhưng dưới 40%, phần lớn vẫn phụ thuộc quảng cáo | G16: Hầu hết khách chỉ mua một lần, phải liên tục tìm khách mới
B17: 12 | C17: Doanh nghiệp có quy trình chăm sóc sau bán hàng được thực hiện nhất quán cho mọi khách? | D17: ❌ Chưa có | E17: Có quy trình rõ ràng (gọi điện, nhắn tin, email) — nhân viên thực hiện được mà không cần nhắc | F17: Có làm nhưng không nhất quán, phụ thuộc vào tâm trạng hoặc chỉ khi nhớ | G17: Chưa có, bán xong là xong
B18: 13 | C18: Bạn biết sản phẩm hoặc dịch vụ nào đang tạo ra phần lớn doanh thu của mình? | D18: ❌ Chưa có | E18: Biết rõ top 3 sản phẩm/dịch vụ chiếm >60% doanh thu, có dữ liệu chứng minh | F18: Biết ước chừng nhưng chưa có số liệu cụ thể để chứng minh | G18: Không biết, bán gì cũng như nhau trong mắt mình
B19: 14 | C19: Tỷ lệ đơn hàng bị hoàn trả, đổi trả hoặc khiếu nại đang ở mức nào? | D19: ✅ Có hệ thống | E19: Dưới 3% — có quy trình xử lý rõ ràng và đang cải thiện liên tục | F19: Từ 3–7% — có xảy ra nhưng chưa tìm được nguyên nhân gốc rễ để xử lý | G19: Trên 7% hoặc không biết tỷ lệ vì chưa bao giờ đo
B20: 15 | C20: Doanh nghiệp có ít nhất 2 kênh bán hàng độc lập đang hoạt động song song? | D20: ✅ Có hệ thống | E20: Có ≥ 2 kênh, không kênh nào chiếm quá 60% doanh thu | F20: Đang có 2 kênh nhưng 1 kênh chiếm trên 80% — còn phụ thuộc nhiều | G20: Chỉ có 1 kênh duy nhất
B21: 16 | C21: Khi có khách hàng phàn nàn hoặc đánh giá tiêu cực, doanh nghiệp xử lý như thế nào? | D21: ✅ Có hệ thống | E21: Có quy trình xử lý rõ ràng, phản hồi trong 24 giờ, có người chịu trách nhiệm | F21: Có xử lý nhưng không nhất quán, đôi khi chậm hoặc bỏ sót | G21: Chưa có quy trình, xử lý theo cảm tính hoặc thường bỏ qua
B22: 17 | C22: Bạn nắm rõ thông tin về nhóm khách hàng thân thiết nhất của mình? | D22: 🔄 Đang xây dựng | E22: Có danh sách khách VIP, biết lịch sử mua hàng và có chiến lược chăm sóc riêng | F22: Biết mặt biết tên nhưng chưa có hệ thống lưu trữ hay chăm sóc bài bản | G22: Chưa phân loại khách hàng, đối xử như nhau với tất cả
B23: 18 | C23: Doanh thu có được phân bổ từ nhiều nguồn thay vì phụ thuộc vào 1 khách hàng lớn hoặc 1 hợp đồng? | D23: 🔄 Đang xây dựng | E23: Không có khách/hợp đồng nào chiếm quá 30% tổng doanh thu | F23: Có 1 nguồn chiếm 30–50% — đang ở ngưỡng rủi ro | G23: Có nguồn chiếm trên 50% — nếu mất nguồn đó sẽ nguy hiểm ngay
B24: 19 | C24: Bạn đo lường được tỷ lệ chuyển đổi từ người hỏi/xem → người mua thực tế? | D24: 🔄 Đang xây dựng | E24: Đo được, biết con số và đang tối ưu từng bước trong phễu | F24: Biết ước chừng nhưng chưa theo dõi hệ thống | G24: Chưa bao giờ đo, không biết mình đang mất khách ở bước nào
B25: 20 | C25: Trong 6 tháng gần nhất, doanh nghiệp có thu thập phản hồi chính thức về mức độ hài lòng của khách hàng? | D25: 🔄 Đang xây dựng | E25: Có khảo sát định kỳ, phân tích kết quả và điều chỉnh dịch vụ theo phản hồi | F25: Có hỏi thăm không chính thức nhưng chưa thu thập có hệ thống | G25: Chưa bao giờ khảo sát, tự cho rằng khách hàng hài lòng
A26: III. VẬN HÀNH & QUY TRÌNH (Tiêu chí #21 – #30)
B27: 21 | C27: Quy trình bán hàng từ lúc khách hỏi đến lúc nhận tiền có được viết thành tài liệu? | D27: ❌ Chưa có | E27: Có SOP bằng văn bản, nhân viên đang thực hiện theo và được cập nhật định kỳ | F27: Có phác thảo quy trình nhưng nhân viên vẫn làm theo nhiều cách khác nhau | G27: Chưa có văn bản, quy trình chỉ nằm trong đầu chủ
B28: 22 | C28: Nếu nhân viên chủ chốt nghỉ đột xuất, hoạt động kinh doanh vẫn diễn ra bình thường? | D28: ❌ Chưa có | E28: Có người thay thế được ngay, quy trình đủ rõ để người khác tiếp quản | F28: Bị xáo trộn một chút nhưng vẫn xử lý được sau 1–2 ngày | G28: Gần như tê liệt — không ai biết làm thay, buộc phải gọi người nghỉ quay lại
B29: 23 | C29: Tồn kho hàng hóa hoặc nguyên vật liệu có được theo dõi bằng công cụ (phần mềm hoặc bảng tính)? | D29: 🔄 Đang xây dựng | E29: Có hệ thống theo dõi real-time, biết số lượng tồn chính xác bất kỳ lúc nào | F29: Có theo dõi nhưng không liên tục, phải kiểm kho thủ công định kỳ | G29: Dựa vào trí nhớ hoặc ước tính, không có công cụ theo dõi
B30: 24 | C30: Doanh nghiệp có cơ chế phát hiện thất thoát tiền hoặc hàng trong vòng 24 giờ? | D30: 🔄 Đang xây dựng | E30: Có kiểm tra chéo hàng ngày, sai lệch được phát hiện và xử lý ngay trong ngày | F30: Phát hiện được nhưng thường mất vài ngày mới nhận ra | G30: Chỉ phát hiện cuối tháng khi cộng sổ, thiệt hại đã xảy ra mới biết
B31: 25 | C31: Tỷ lệ sai sót trong vận hành (giao nhầm hàng, làm sai dịch vụ, phải làm lại) đang ở mức nào? | D31: 🔄 Đang xây dựng | E31: Dưới 2% — có quy trình kiểm tra chất lượng trước khi giao tới khách | F31: Từ 2–5% — có xảy ra nhưng chưa giải quyết được triệt để | G31: Trên 5% hoặc không biết tỷ lệ vì chưa bao giờ đo
B32: 26 | C32: Khi giao việc cho nhân viên, mức độ hoàn thành đúng hạn và đúng yêu cầu như thế nào? | D32: ✅ Có hệ thống | E32: Trên 80% việc hoàn thành đúng yêu cầu mà không cần nhắc lại | F32: Khoảng 50–80% — phải nhắc thường xuyên hoặc phải sửa lại | G32: Dưới 50% — giao việc xong phải theo sau để kiểm tra liên tục
B33: 27 | C33: Doanh nghiệp có sử dụng phần mềm quản lý (bán hàng, kho, kế toán) thay vì ghi tay hoặc dùng nhóm chat để theo dõi đơn hàng? | D33: ✅ Có hệ thống | E33: Có phần mềm, toàn bộ đội ngũ đang sử dụng nhất quán | F33: Có phần mềm nhưng chỉ dùng một phần, vẫn còn ghi tay song song | G33: Chưa có phần mềm, dùng zalo/messenger hoặc ghi tay
B34: 28 | C34: Việc nhập hàng hoặc đặt nguyên liệu được quyết định dựa trên điều gì? | D34: ✅ Có hệ thống | E34: Dựa trên dữ liệu bán hàng thực tế và dự báo nhu cầu | F34: Kết hợp giữa số liệu và cảm tính, đôi khi vẫn nhập sai | G34: Hoàn toàn theo cảm tính hoặc theo thói quen cũ
B35: 29 | C35: Dữ liệu quan trọng (mật khẩu phần mềm, tài khoản mạng xã hội, danh sách khách hàng) có được lưu trữ an toàn và phân quyền truy cập? | D35: ✅ Có hệ thống | E35: Có hệ thống lưu trữ an toàn, có phân quyền — không phụ thuộc vào trí nhớ một người | F35: Có lưu nhưng chưa phân quyền rõ ràng, dễ bị lộ hoặc mất quyền kiểm soát | G35: Không có hệ thống lưu trữ, phụ thuộc vào trí nhớ hoặc điện thoại cá nhân
B36: 30 | C36: Bạn có ít nhất 5 chỉ số vận hành (doanh thu ngày, số đơn, tỷ lệ hoàn hàng/ làm lại dịch vụ…) được theo dõi định kỳ hàng tuần? | D36: ✅ Có hệ thống | E36: Có dashboard theo dõi ít nhất 5 KPI ops hàng tuần, có phân tích xu hướng | F36: Theo dõi 1–3 chỉ số cơ bản, chưa đủ toàn diện | G36: Chưa có chỉ số nào được theo dõi hệ thống
A37: IV. NHÂN SỰ & ĐỘI NGŨ (Tiêu chí #31 – #40)
B38: 31 | C38: Mỗi nhân viên có bản mô tả công việc với KPI đo lường và tiêu chí đánh giá rõ ràng? | D38: ❌ Chưa có | E38: Tất cả vị trí có JD và KPI bằng văn bản, nhân viên hiểu và ký xác nhận | F38: Một số vị trí có JD nhưng chưa đầy đủ hoặc chưa cập nhật | G38: Chưa có JD cho bất kỳ vị trí nào, phân công bằng miệng
B39: 32 | C39: Bạn đo được năng suất của từng nhân viên bằng con số cụ thể? | D39: ❌ Chưa có | E39: Có chỉ số năng suất cho từng người (doanh thu/người, đơn/ca…), xem lại hàng tuần | F39: Biết ước chừng ai làm tốt hơn nhưng không có số liệu để chứng minh | G39: Không đo được, không biết ai đang làm hiệu quả và ai đang 'ngồi chơi'
B40: 33 | C40: Khi nhân viên mới vào, họ mất bao lâu để làm việc độc lập mà không cần bạn cầm tay chỉ việc? | D40: ❌ Chưa có | E40: 3–7 ngày — có quy trình onboarding bài bản và tài liệu hướng dẫn đầy đủ | F40: 1–2 tuần — có hướng dẫn cơ bản nhưng phải kèm cặp nhiều | G40: Vài tuần đến vài tháng — phải cầm tay chỉ việc liên tục, rất tốn sức
...

Sheet 📈 Kết Quả & Chẩn Đoán
A1: 📈 KẾT QUẢ CHẨN ĐOÁN · BẢN X-QUANG 50 TIÊU CHÍ · YUP Education
A2: Tất cả số liệu tính tự động từ sheet 'Bảng Chẩn Đoán' — Không cần nhập thêm gì!
A4: KẾT QUẢ TỔNG QUAN
A5: Tổng điểm đạt được | C5: ='📝 Bảng Chẩn Đoán'!D59 -> 53 | D5: / 100 điểm
A6: Tỷ lệ sức khỏe tổng thể | C6: ='📝 Bảng Chẩn Đoán'!D59/100 -> 0.53 | D6: % (mục tiêu: ≥ 60%)
A7: Số tiêu chí ✅ Có hệ thống | C7: =COUNTIF('📝 Bảng Chẩn Đoán'!D4:D58,"✅ Có hệ thống") -> 17 | D7: / 50 tiêu chí
A8: Số tiêu chí 🔄 Đang xây dựng | C8: =COUNTIF('📝 Bảng Chẩn Đoán'!D4:D58,"🔄 Đang xây dựng") -> 19 | D8: tiêu chí cần hoàn thiện
A9: Số tiêu chí ❌ Chưa có | C9: =COUNTIF('📝 Bảng Chẩn Đoán'!D4:D58,"❌ Chưa có") -> 14 | D9: tiêu chí cần bắt đầu ngay
A11: ĐIỂM THEO 5 TRỤ CỘT (tối đa 20 điểm mỗi trụ cột)
B12: Trụ cột | C12: Điểm đạt | D12: / 20 | E12: Tỷ lệ % | F12: Chẩn đoán & Hành động
B13: I. TÀI CHÍNH & DÒNG TIỀN | C13: =2*COUNTIF('📝 Bảng Chẩn Đoán'!D5:D14,"✅ Có hệ thống")+COUNTIF('📝 Bảng Chẩn Đoán'!D5:D14,"🔄 Đang xây dựng") -> 17 | D13: 20 | E13: =C13/20 -> 0.85 | F13: =IF(C13<=6,"🔴 Nguy hiểm – Ưu tiên xử lý ngay",IF(C13<=10,"🟡 Yếu – Cải thiện trong 30 ngày",IF(C13<=14,"🔵 Đang phát triển – Tối ưu thêm",IF(C13<=18,"🟢 Tốt – Duy trì & nâng cao","✅ Xuất sắc – Mô hình hóa")))) -> 🟢 Tốt – Duy trì & nâng cao
B14: II. DOANH THU & KHÁCH HÀNG | C14: =2*COUNTIF('📝 Bảng Chẩn Đoán'!D16:D25,"✅ Có hệ thống")+COUNTIF('📝 Bảng Chẩn Đoán'!D16:D25,"🔄 Đang xây dựng") -> 10 | D14: 20 | E14: =C14/20 -> 0.5 | F14: =IF(C14<=6,"🔴 Nguy hiểm – Ưu tiên xử lý ngay",IF(C14<=10,"🟡 Yếu – Cải thiện trong 30 ngày",IF(C14<=14,"🔵 Đang phát triển – Tối ưu thêm",IF(C14<=18,"🟢 Tốt – Duy trì & nâng cao","✅ Xuất sắc – Mô hình hóa")))) -> 🟡 Yếu – Cải thiện trong 30 ngày
B15: III. VẬN HÀNH & QUY TRÌNH | C15: =2*COUNTIF('📝 Bảng Chẩn Đoán'!D27:D36,"✅ Có hệ thống")+COUNTIF('📝 Bảng Chẩn Đoán'!D27:D36,"🔄 Đang xây dựng") -> 13 | D15: 20 | E15: =C15/20 -> 0.65 | F15: =IF(C15<=6,"🔴 Nguy hiểm – Ưu tiên xử lý ngay",IF(C15<=10,"🟡 Yếu – Cải thiện trong 30 ngày",IF(C15<=14,"🔵 Đang phát triển – Tối ưu thêm",IF(C15<=18,"🟢 Tốt – Duy trì & nâng cao","✅ Xuất sắc – Mô hình hóa")))) -> 🔵 Đang phát triển – Tối ưu thêm
B16: IV. NHÂN SỰ & ĐỘI NGŨ | C16: =2*COUNTIF('📝 Bảng Chẩn Đoán'!D38:D47,"✅ Có hệ thống")+COUNTIF('📝 Bảng Chẩn Đoán'!D38:D47,"🔄 Đang xây dựng") -> 3 | D16: 20 | E16: =C16/20 -> 0.15 | F16: =IF(C16<=6,"🔴 Nguy hiểm – Ưu tiên xử lý ngay",IF(C16<=10,"🟡 Yếu – Cải thiện trong 30 ngày",IF(C16<=14,"🔵 Đang phát triển – Tối ưu thêm",IF(C16<=18,"🟢 Tốt – Duy trì & nâng cao","✅ Xuất sắc – Mô hình hóa")))) -> 🔴 Nguy hiểm – Ưu tiên xử lý ngay
B17: V. LÃNH ĐẠO & TĂNG TRƯỞNG | C17: =2*COUNTIF('📝 Bảng Chẩn Đoán'!D49:D58,"✅ Có hệ thống")+COUNTIF('📝 Bảng Chẩn Đoán'!D49:D58,"🔄 Đang xây dựng") -> 10 | D17: 20 | E17: =C17/20 -> 0.5 | F17: =IF(C17<=6,"🔴 Nguy hiểm – Ưu tiên xử lý ngay",IF(C17<=10,"🟡 Yếu – Cải thiện trong 30 ngày",IF(C17<=14,"🔵 Đang phát triển – Tối ưu thêm",IF(C17<=18,"🟢 Tốt – Duy trì & nâng cao","✅ Xuất sắc – Mô hình hóa")))) -> 🟡 Yếu – Cải thiện trong 30 ngày
A19: CHẨN ĐOÁN TỔNG THỂ — ĐỌC KẾT QUẢ CỦA BẠN
A20: 0–39 điểm (< 40%) | C20: 🔴 KHẨN CẤP | E20: Nhiều lỗ hổng nguy hiểm đang tồn tại. Dừng mở rộng, tập trung vá lỗ hổng trước tiên.
A21: 40–59 điểm (40–59%) | C21: 🟡 CẦN CẢI THIỆN | E21: Có nền tảng nhưng nhiều điểm nghẽn. Chọn 2–3 trụ cột yếu nhất để cải thiện trong 90 ngày.
A22: 60–74 điểm (60–74%) | C22: 🔵 ĐANG PHÁT TRIỂN | E22: Vận hành ổn nhưng chưa tối ưu. Bắt đầu hệ thống hóa và phân quyền để thoát bẫy 'khổ chủ'.
A23: 75–89 điểm (75–89%) | C23: 🟢 SỨC KHỎE TỐT | E23: Nền tảng vững chắc. Sẵn sàng tăng trưởng có hệ thống — tập trung vào chiến lược mở rộng.
A24: 90–100 điểm (90–100%) | C24: ✅ DOANH NGHIỆP BỀN VỮNG | E24: Đẳng cấp vận hành cao. Sẵn sàng mở rộng quy mô, nhượng quyền hoặc thu hút nhà đầu tư.
A26: LỘ TRÌNH HÀNH ĐỘNG — Điền sau khi xem kết quả (mang đến Buổi 2)
B27: Trụ cột yếu nhất | C27: Tiêu chí ❌ nổi bật | D27: Hậu quả đang xảy ra | E27: Hành động cụ thể | F27: Deadline
A31: 💡 Mang bảng chẩn đoán đến Buổi 2 — YUP sẽ hỗ trợ thiết kế Lộ trình hành động 90 ngày cho riêng bạn.
A32: © YUP Education · Tài liệu độc quyền – Không phát tán · Giải Mã 2026
